2024-03-04 18:44:59,109 [INFO]: Watching for file changes with StatReloader
2024-03-04 18:49:15,329 [INFO]: /Users/Nick_DEV/Documents/DEV/My_project/telebot_helpman/help_work_bot/helpmanbot/manage.py changed, reloading.
2024-03-11 10:55:15,918 [ERROR]: Infinity polling exception: [Errno 2] No such file or directory: 'Instructions'
2024-03-11 10:55:15,919 [ERROR]: Exception traceback:
Traceback (most recent call last):
  File "/Users/Nick_DEV/Documents/DEV/My_project/telebot_helpman/help_work_bot/.venv/lib/python3.9/site-packages/telebot/__init__.py", line 955, in infinity_polling
    self.polling(non_stop=True, timeout=timeout, long_polling_timeout=long_polling_timeout,
  File "/Users/Nick_DEV/Documents/DEV/My_project/telebot_helpman/help_work_bot/.venv/lib/python3.9/site-packages/telebot/__init__.py", line 1043, in polling
    self.__threaded_polling(non_stop=non_stop, interval=interval, timeout=timeout, long_polling_timeout=long_polling_timeout,
  File "/Users/Nick_DEV/Documents/DEV/My_project/telebot_helpman/help_work_bot/.venv/lib/python3.9/site-packages/telebot/__init__.py", line 1118, in __threaded_polling
    raise e
  File "/Users/Nick_DEV/Documents/DEV/My_project/telebot_helpman/help_work_bot/.venv/lib/python3.9/site-packages/telebot/__init__.py", line 1074, in __threaded_polling
    self.worker_pool.raise_exceptions()
  File "/Users/Nick_DEV/Documents/DEV/My_project/telebot_helpman/help_work_bot/.venv/lib/python3.9/site-packages/telebot/util.py", line 147, in raise_exceptions
    raise self.exception_info
  File "/Users/Nick_DEV/Documents/DEV/My_project/telebot_helpman/help_work_bot/.venv/lib/python3.9/site-packages/telebot/util.py", line 90, in run
    task(*args, **kwargs)
  File "/Users/Nick_DEV/Documents/DEV/My_project/telebot_helpman/help_work_bot/.venv/lib/python3.9/site-packages/telebot/__init__.py", line 6770, in _run_middlewares_and_handler
    result = handler['function'](message)
  File "/Users/Nick_DEV/Documents/DEV/My_project/telebot_helpman/help_work_bot/helpmanbot/telegram_bot/management/commands/main.py", line 74, in handle_start
    for item in os.listdir(current_path):
FileNotFoundError: [Errno 2] No such file or directory: 'Instructions'

2024-03-11 10:55:35,605 [ERROR]: Infinity polling: polling exited
2024-03-11 10:55:35,605 [ERROR]: Break infinity polling
2024-03-11 19:40:47,075 [ERROR]: Infinity polling exception: [Errno 2] No such file or directory: '..Instructions'
2024-03-11 19:40:47,076 [ERROR]: Exception traceback:
Traceback (most recent call last):
  File "/Users/Nick_DEV/Documents/DEV/My_project/telebot_helpman/help_work_bot/.venv/lib/python3.9/site-packages/telebot/__init__.py", line 955, in infinity_polling
    self.polling(non_stop=True, timeout=timeout, long_polling_timeout=long_polling_timeout,
  File "/Users/Nick_DEV/Documents/DEV/My_project/telebot_helpman/help_work_bot/.venv/lib/python3.9/site-packages/telebot/__init__.py", line 1043, in polling
    self.__threaded_polling(non_stop=non_stop, interval=interval, timeout=timeout, long_polling_timeout=long_polling_timeout,
  File "/Users/Nick_DEV/Documents/DEV/My_project/telebot_helpman/help_work_bot/.venv/lib/python3.9/site-packages/telebot/__init__.py", line 1118, in __threaded_polling
    raise e
  File "/Users/Nick_DEV/Documents/DEV/My_project/telebot_helpman/help_work_bot/.venv/lib/python3.9/site-packages/telebot/__init__.py", line 1074, in __threaded_polling
    self.worker_pool.raise_exceptions()
  File "/Users/Nick_DEV/Documents/DEV/My_project/telebot_helpman/help_work_bot/.venv/lib/python3.9/site-packages/telebot/util.py", line 147, in raise_exceptions
    raise self.exception_info
  File "/Users/Nick_DEV/Documents/DEV/My_project/telebot_helpman/help_work_bot/.venv/lib/python3.9/site-packages/telebot/util.py", line 90, in run
    task(*args, **kwargs)
  File "/Users/Nick_DEV/Documents/DEV/My_project/telebot_helpman/help_work_bot/.venv/lib/python3.9/site-packages/telebot/__init__.py", line 6770, in _run_middlewares_and_handler
    result = handler['function'](message)
  File "/Users/Nick_DEV/Documents/DEV/My_project/telebot_helpman/help_work_bot/helpmanbot/telegram_bot/management/commands/main.py", line 74, in handle_start
    for item in os.listdir(current_path):
FileNotFoundError: [Errno 2] No such file or directory: '..Instructions'

2024-03-11 19:41:01,795 [ERROR]: Infinity polling: polling exited
2024-03-11 19:41:01,797 [ERROR]: Break infinity polling
2024-03-11 19:41:06,205 [ERROR]: Infinity polling exception: [Errno 2] No such file or directory: '//Instructions'
2024-03-11 19:41:06,206 [ERROR]: Exception traceback:
Traceback (most recent call last):
  File "/Users/Nick_DEV/Documents/DEV/My_project/telebot_helpman/help_work_bot/.venv/lib/python3.9/site-packages/telebot/__init__.py", line 955, in infinity_polling
    self.polling(non_stop=True, timeout=timeout, long_polling_timeout=long_polling_timeout,
  File "/Users/Nick_DEV/Documents/DEV/My_project/telebot_helpman/help_work_bot/.venv/lib/python3.9/site-packages/telebot/__init__.py", line 1043, in polling
    self.__threaded_polling(non_stop=non_stop, interval=interval, timeout=timeout, long_polling_timeout=long_polling_timeout,
  File "/Users/Nick_DEV/Documents/DEV/My_project/telebot_helpman/help_work_bot/.venv/lib/python3.9/site-packages/telebot/__init__.py", line 1118, in __threaded_polling
    raise e
  File "/Users/Nick_DEV/Documents/DEV/My_project/telebot_helpman/help_work_bot/.venv/lib/python3.9/site-packages/telebot/__init__.py", line 1074, in __threaded_polling
    self.worker_pool.raise_exceptions()
  File "/Users/Nick_DEV/Documents/DEV/My_project/telebot_helpman/help_work_bot/.venv/lib/python3.9/site-packages/telebot/util.py", line 147, in raise_exceptions
    raise self.exception_info
  File "/Users/Nick_DEV/Documents/DEV/My_project/telebot_helpman/help_work_bot/.venv/lib/python3.9/site-packages/telebot/util.py", line 90, in run
    task(*args, **kwargs)
  File "/Users/Nick_DEV/Documents/DEV/My_project/telebot_helpman/help_work_bot/.venv/lib/python3.9/site-packages/telebot/__init__.py", line 6770, in _run_middlewares_and_handler
    result = handler['function'](message)
  File "/Users/Nick_DEV/Documents/DEV/My_project/telebot_helpman/help_work_bot/helpmanbot/telegram_bot/management/commands/main.py", line 74, in handle_start
    for item in os.listdir(current_path):
FileNotFoundError: [Errno 2] No such file or directory: '//Instructions'

2024-03-11 19:42:05,836 [ERROR]: Infinity polling: polling exited
2024-03-11 19:42:05,836 [ERROR]: Break infinity polling
2024-03-11 19:42:12,637 [ERROR]: Infinity polling exception: [Errno 2] No such file or directory: '../../Instructions'
2024-03-11 19:42:12,639 [ERROR]: Exception traceback:
Traceback (most recent call last):
  File "/Users/Nick_DEV/Documents/DEV/My_project/telebot_helpman/help_work_bot/.venv/lib/python3.9/site-packages/telebot/__init__.py", line 955, in infinity_polling
    self.polling(non_stop=True, timeout=timeout, long_polling_timeout=long_polling_timeout,
  File "/Users/Nick_DEV/Documents/DEV/My_project/telebot_helpman/help_work_bot/.venv/lib/python3.9/site-packages/telebot/__init__.py", line 1043, in polling
    self.__threaded_polling(non_stop=non_stop, interval=interval, timeout=timeout, long_polling_timeout=long_polling_timeout,
  File "/Users/Nick_DEV/Documents/DEV/My_project/telebot_helpman/help_work_bot/.venv/lib/python3.9/site-packages/telebot/__init__.py", line 1118, in __threaded_polling
    raise e
  File "/Users/Nick_DEV/Documents/DEV/My_project/telebot_helpman/help_work_bot/.venv/lib/python3.9/site-packages/telebot/__init__.py", line 1074, in __threaded_polling
    self.worker_pool.raise_exceptions()
  File "/Users/Nick_DEV/Documents/DEV/My_project/telebot_helpman/help_work_bot/.venv/lib/python3.9/site-packages/telebot/util.py", line 147, in raise_exceptions
    raise self.exception_info
  File "/Users/Nick_DEV/Documents/DEV/My_project/telebot_helpman/help_work_bot/.venv/lib/python3.9/site-packages/telebot/util.py", line 90, in run
    task(*args, **kwargs)
  File "/Users/Nick_DEV/Documents/DEV/My_project/telebot_helpman/help_work_bot/.venv/lib/python3.9/site-packages/telebot/__init__.py", line 6770, in _run_middlewares_and_handler
    result = handler['function'](message)
  File "/Users/Nick_DEV/Documents/DEV/My_project/telebot_helpman/help_work_bot/helpmanbot/telegram_bot/management/commands/main.py", line 74, in handle_start
    for item in os.listdir(current_path):
FileNotFoundError: [Errno 2] No such file or directory: '../../Instructions'

2024-03-11 19:42:17,511 [ERROR]: Infinity polling: polling exited
2024-03-11 19:42:17,512 [ERROR]: Break infinity polling
2024-03-11 19:42:30,530 [ERROR]: Infinity polling exception: [Errno 2] No such file or directory: '../../../Instructions'
2024-03-11 19:42:30,536 [ERROR]: Exception traceback:
Traceback (most recent call last):
  File "/Users/Nick_DEV/Documents/DEV/My_project/telebot_helpman/help_work_bot/.venv/lib/python3.9/site-packages/telebot/__init__.py", line 955, in infinity_polling
    self.polling(non_stop=True, timeout=timeout, long_polling_timeout=long_polling_timeout,
  File "/Users/Nick_DEV/Documents/DEV/My_project/telebot_helpman/help_work_bot/.venv/lib/python3.9/site-packages/telebot/__init__.py", line 1043, in polling
    self.__threaded_polling(non_stop=non_stop, interval=interval, timeout=timeout, long_polling_timeout=long_polling_timeout,
  File "/Users/Nick_DEV/Documents/DEV/My_project/telebot_helpman/help_work_bot/.venv/lib/python3.9/site-packages/telebot/__init__.py", line 1118, in __threaded_polling
    raise e
  File "/Users/Nick_DEV/Documents/DEV/My_project/telebot_helpman/help_work_bot/.venv/lib/python3.9/site-packages/telebot/__init__.py", line 1074, in __threaded_polling
    self.worker_pool.raise_exceptions()
  File "/Users/Nick_DEV/Documents/DEV/My_project/telebot_helpman/help_work_bot/.venv/lib/python3.9/site-packages/telebot/util.py", line 147, in raise_exceptions
    raise self.exception_info
  File "/Users/Nick_DEV/Documents/DEV/My_project/telebot_helpman/help_work_bot/.venv/lib/python3.9/site-packages/telebot/util.py", line 90, in run
    task(*args, **kwargs)
  File "/Users/Nick_DEV/Documents/DEV/My_project/telebot_helpman/help_work_bot/.venv/lib/python3.9/site-packages/telebot/__init__.py", line 6770, in _run_middlewares_and_handler
    result = handler['function'](message)
  File "/Users/Nick_DEV/Documents/DEV/My_project/telebot_helpman/help_work_bot/helpmanbot/telegram_bot/management/commands/main.py", line 74, in handle_start
    for item in os.listdir(current_path):
FileNotFoundError: [Errno 2] No such file or directory: '../../../Instructions'

2024-03-11 19:43:38,803 [ERROR]: Infinity polling: polling exited
2024-03-11 19:43:38,803 [ERROR]: Break infinity polling
2024-03-11 19:43:42,374 [ERROR]: Infinity polling exception: [Errno 2] No such file or directory: 'helpmanbot/Instructions'
2024-03-11 19:43:42,390 [ERROR]: Exception traceback:
Traceback (most recent call last):
  File "/Users/Nick_DEV/Documents/DEV/My_project/telebot_helpman/help_work_bot/.venv/lib/python3.9/site-packages/telebot/__init__.py", line 955, in infinity_polling
    self.polling(non_stop=True, timeout=timeout, long_polling_timeout=long_polling_timeout,
  File "/Users/Nick_DEV/Documents/DEV/My_project/telebot_helpman/help_work_bot/.venv/lib/python3.9/site-packages/telebot/__init__.py", line 1043, in polling
    self.__threaded_polling(non_stop=non_stop, interval=interval, timeout=timeout, long_polling_timeout=long_polling_timeout,
  File "/Users/Nick_DEV/Documents/DEV/My_project/telebot_helpman/help_work_bot/.venv/lib/python3.9/site-packages/telebot/__init__.py", line 1118, in __threaded_polling
    raise e
  File "/Users/Nick_DEV/Documents/DEV/My_project/telebot_helpman/help_work_bot/.venv/lib/python3.9/site-packages/telebot/__init__.py", line 1074, in __threaded_polling
    self.worker_pool.raise_exceptions()
  File "/Users/Nick_DEV/Documents/DEV/My_project/telebot_helpman/help_work_bot/.venv/lib/python3.9/site-packages/telebot/util.py", line 147, in raise_exceptions
    raise self.exception_info
  File "/Users/Nick_DEV/Documents/DEV/My_project/telebot_helpman/help_work_bot/.venv/lib/python3.9/site-packages/telebot/util.py", line 90, in run
    task(*args, **kwargs)
  File "/Users/Nick_DEV/Documents/DEV/My_project/telebot_helpman/help_work_bot/.venv/lib/python3.9/site-packages/telebot/__init__.py", line 6770, in _run_middlewares_and_handler
    result = handler['function'](message)
  File "/Users/Nick_DEV/Documents/DEV/My_project/telebot_helpman/help_work_bot/helpmanbot/telegram_bot/management/commands/main.py", line 74, in handle_start
    for item in os.listdir(current_path):
FileNotFoundError: [Errno 2] No such file or directory: 'helpmanbot/Instructions'

2024-03-11 19:44:21,503 [ERROR]: Infinity polling: polling exited
2024-03-11 19:44:21,511 [ERROR]: Break infinity polling
2024-03-11 19:44:25,022 [ERROR]: Infinity polling exception: [Errno 2] No such file or directory: './helpmanbot/Instructions'
2024-03-11 19:44:25,023 [ERROR]: Exception traceback:
Traceback (most recent call last):
  File "/Users/Nick_DEV/Documents/DEV/My_project/telebot_helpman/help_work_bot/.venv/lib/python3.9/site-packages/telebot/__init__.py", line 955, in infinity_polling
    self.polling(non_stop=True, timeout=timeout, long_polling_timeout=long_polling_timeout,
  File "/Users/Nick_DEV/Documents/DEV/My_project/telebot_helpman/help_work_bot/.venv/lib/python3.9/site-packages/telebot/__init__.py", line 1043, in polling
    self.__threaded_polling(non_stop=non_stop, interval=interval, timeout=timeout, long_polling_timeout=long_polling_timeout,
  File "/Users/Nick_DEV/Documents/DEV/My_project/telebot_helpman/help_work_bot/.venv/lib/python3.9/site-packages/telebot/__init__.py", line 1118, in __threaded_polling
    raise e
  File "/Users/Nick_DEV/Documents/DEV/My_project/telebot_helpman/help_work_bot/.venv/lib/python3.9/site-packages/telebot/__init__.py", line 1074, in __threaded_polling
    self.worker_pool.raise_exceptions()
  File "/Users/Nick_DEV/Documents/DEV/My_project/telebot_helpman/help_work_bot/.venv/lib/python3.9/site-packages/telebot/util.py", line 147, in raise_exceptions
    raise self.exception_info
  File "/Users/Nick_DEV/Documents/DEV/My_project/telebot_helpman/help_work_bot/.venv/lib/python3.9/site-packages/telebot/util.py", line 90, in run
    task(*args, **kwargs)
  File "/Users/Nick_DEV/Documents/DEV/My_project/telebot_helpman/help_work_bot/.venv/lib/python3.9/site-packages/telebot/__init__.py", line 6770, in _run_middlewares_and_handler
    result = handler['function'](message)
  File "/Users/Nick_DEV/Documents/DEV/My_project/telebot_helpman/help_work_bot/helpmanbot/telegram_bot/management/commands/main.py", line 74, in handle_start
    for item in os.listdir(current_path):
FileNotFoundError: [Errno 2] No such file or directory: './helpmanbot/Instructions'

2024-03-11 19:44:55,522 [ERROR]: Infinity polling: polling exited
2024-03-11 19:44:55,530 [ERROR]: Break infinity polling
2024-03-11 19:44:59,146 [ERROR]: Infinity polling exception: [Errno 2] No such file or directory: '../../../../Instructions'
2024-03-11 19:44:59,148 [ERROR]: Exception traceback:
Traceback (most recent call last):
  File "/Users/Nick_DEV/Documents/DEV/My_project/telebot_helpman/help_work_bot/.venv/lib/python3.9/site-packages/telebot/__init__.py", line 955, in infinity_polling
    self.polling(non_stop=True, timeout=timeout, long_polling_timeout=long_polling_timeout,
  File "/Users/Nick_DEV/Documents/DEV/My_project/telebot_helpman/help_work_bot/.venv/lib/python3.9/site-packages/telebot/__init__.py", line 1043, in polling
    self.__threaded_polling(non_stop=non_stop, interval=interval, timeout=timeout, long_polling_timeout=long_polling_timeout,
  File "/Users/Nick_DEV/Documents/DEV/My_project/telebot_helpman/help_work_bot/.venv/lib/python3.9/site-packages/telebot/__init__.py", line 1118, in __threaded_polling
    raise e
  File "/Users/Nick_DEV/Documents/DEV/My_project/telebot_helpman/help_work_bot/.venv/lib/python3.9/site-packages/telebot/__init__.py", line 1074, in __threaded_polling
    self.worker_pool.raise_exceptions()
  File "/Users/Nick_DEV/Documents/DEV/My_project/telebot_helpman/help_work_bot/.venv/lib/python3.9/site-packages/telebot/util.py", line 147, in raise_exceptions
    raise self.exception_info
  File "/Users/Nick_DEV/Documents/DEV/My_project/telebot_helpman/help_work_bot/.venv/lib/python3.9/site-packages/telebot/util.py", line 90, in run
    task(*args, **kwargs)
  File "/Users/Nick_DEV/Documents/DEV/My_project/telebot_helpman/help_work_bot/.venv/lib/python3.9/site-packages/telebot/__init__.py", line 6770, in _run_middlewares_and_handler
    result = handler['function'](message)
  File "/Users/Nick_DEV/Documents/DEV/My_project/telebot_helpman/help_work_bot/helpmanbot/telegram_bot/management/commands/main.py", line 74, in handle_start
    for item in os.listdir(current_path):
FileNotFoundError: [Errno 2] No such file or directory: '../../../../Instructions'

2024-03-11 21:47:23,831 [ERROR]: Infinity polling exception: HTTPSConnectionPool(host='api.telegram.org', port=443): Read timed out. (read timeout=25)
2024-03-11 21:47:23,835 [ERROR]: Exception traceback:
Traceback (most recent call last):
  File "/Users/Nick_DEV/Documents/DEV/My_project/telebot_helpman/help_work_bot/.venv/lib/python3.9/site-packages/urllib3/connectionpool.py", line 536, in _make_request
    response = conn.getresponse()
  File "/Users/Nick_DEV/Documents/DEV/My_project/telebot_helpman/help_work_bot/.venv/lib/python3.9/site-packages/urllib3/connection.py", line 454, in getresponse
    httplib_response = super().getresponse()
  File "/usr/local/Cellar/python@3.9/3.9.18/Frameworks/Python.framework/Versions/3.9/lib/python3.9/http/client.py", line 1377, in getresponse
    response.begin()
  File "/usr/local/Cellar/python@3.9/3.9.18/Frameworks/Python.framework/Versions/3.9/lib/python3.9/http/client.py", line 320, in begin
    version, status, reason = self._read_status()
  File "/usr/local/Cellar/python@3.9/3.9.18/Frameworks/Python.framework/Versions/3.9/lib/python3.9/http/client.py", line 281, in _read_status
    line = str(self.fp.readline(_MAXLINE + 1), "iso-8859-1")
  File "/usr/local/Cellar/python@3.9/3.9.18/Frameworks/Python.framework/Versions/3.9/lib/python3.9/socket.py", line 704, in readinto
    return self._sock.recv_into(b)
  File "/usr/local/Cellar/python@3.9/3.9.18/Frameworks/Python.framework/Versions/3.9/lib/python3.9/ssl.py", line 1275, in recv_into
    return self.read(nbytes, buffer)
  File "/usr/local/Cellar/python@3.9/3.9.18/Frameworks/Python.framework/Versions/3.9/lib/python3.9/ssl.py", line 1133, in read
    return self._sslobj.read(len, buffer)
socket.timeout: The read operation timed out

The above exception was the direct cause of the following exception:

Traceback (most recent call last):
  File "/Users/Nick_DEV/Documents/DEV/My_project/telebot_helpman/help_work_bot/.venv/lib/python3.9/site-packages/requests/adapters.py", line 486, in send
    resp = conn.urlopen(
  File "/Users/Nick_DEV/Documents/DEV/My_project/telebot_helpman/help_work_bot/.venv/lib/python3.9/site-packages/urllib3/connectionpool.py", line 844, in urlopen
    retries = retries.increment(
  File "/Users/Nick_DEV/Documents/DEV/My_project/telebot_helpman/help_work_bot/.venv/lib/python3.9/site-packages/urllib3/util/retry.py", line 470, in increment
    raise reraise(type(error), error, _stacktrace)
  File "/Users/Nick_DEV/Documents/DEV/My_project/telebot_helpman/help_work_bot/.venv/lib/python3.9/site-packages/urllib3/util/util.py", line 39, in reraise
    raise value
  File "/Users/Nick_DEV/Documents/DEV/My_project/telebot_helpman/help_work_bot/.venv/lib/python3.9/site-packages/urllib3/connectionpool.py", line 790, in urlopen
    response = self._make_request(
  File "/Users/Nick_DEV/Documents/DEV/My_project/telebot_helpman/help_work_bot/.venv/lib/python3.9/site-packages/urllib3/connectionpool.py", line 538, in _make_request
    self._raise_timeout(err=e, url=url, timeout_value=read_timeout)
  File "/Users/Nick_DEV/Documents/DEV/My_project/telebot_helpman/help_work_bot/.venv/lib/python3.9/site-packages/urllib3/connectionpool.py", line 370, in _raise_timeout
    raise ReadTimeoutError(
urllib3.exceptions.ReadTimeoutError: HTTPSConnectionPool(host='api.telegram.org', port=443): Read timed out. (read timeout=25)

During handling of the above exception, another exception occurred:

Traceback (most recent call last):
  File "/Users/Nick_DEV/Documents/DEV/My_project/telebot_helpman/help_work_bot/.venv/lib/python3.9/site-packages/telebot/__init__.py", line 955, in infinity_polling
    self.polling(non_stop=True, timeout=timeout, long_polling_timeout=long_polling_timeout,
  File "/Users/Nick_DEV/Documents/DEV/My_project/telebot_helpman/help_work_bot/.venv/lib/python3.9/site-packages/telebot/__init__.py", line 1043, in polling
    self.__threaded_polling(non_stop=non_stop, interval=interval, timeout=timeout, long_polling_timeout=long_polling_timeout,
  File "/Users/Nick_DEV/Documents/DEV/My_project/telebot_helpman/help_work_bot/.venv/lib/python3.9/site-packages/telebot/__init__.py", line 1118, in __threaded_polling
    raise e
  File "/Users/Nick_DEV/Documents/DEV/My_project/telebot_helpman/help_work_bot/.venv/lib/python3.9/site-packages/telebot/__init__.py", line 1073, in __threaded_polling
    polling_thread.raise_exceptions()
  File "/Users/Nick_DEV/Documents/DEV/My_project/telebot_helpman/help_work_bot/.venv/lib/python3.9/site-packages/telebot/util.py", line 108, in raise_exceptions
    raise self.exception_info
  File "/Users/Nick_DEV/Documents/DEV/My_project/telebot_helpman/help_work_bot/.venv/lib/python3.9/site-packages/telebot/util.py", line 90, in run
    task(*args, **kwargs)
  File "/Users/Nick_DEV/Documents/DEV/My_project/telebot_helpman/help_work_bot/.venv/lib/python3.9/site-packages/telebot/__init__.py", line 649, in __retrieve_updates
    updates = self.get_updates(offset=(self.last_update_id + 1),
  File "/Users/Nick_DEV/Documents/DEV/My_project/telebot_helpman/help_work_bot/.venv/lib/python3.9/site-packages/telebot/__init__.py", line 623, in get_updates
    json_updates = apihelper.get_updates(self.token, offset, limit, timeout, allowed_updates, long_polling_timeout)
  File "/Users/Nick_DEV/Documents/DEV/My_project/telebot_helpman/help_work_bot/.venv/lib/python3.9/site-packages/telebot/apihelper.py", line 321, in get_updates
    return _make_request(token, method_url, params=payload)
  File "/Users/Nick_DEV/Documents/DEV/My_project/telebot_helpman/help_work_bot/.venv/lib/python3.9/site-packages/telebot/apihelper.py", line 156, in _make_request
    result = _get_req_session().request(
  File "/Users/Nick_DEV/Documents/DEV/My_project/telebot_helpman/help_work_bot/.venv/lib/python3.9/site-packages/requests/sessions.py", line 589, in request
    resp = self.send(prep, **send_kwargs)
  File "/Users/Nick_DEV/Documents/DEV/My_project/telebot_helpman/help_work_bot/.venv/lib/python3.9/site-packages/requests/sessions.py", line 703, in send
    r = adapter.send(request, **kwargs)
  File "/Users/Nick_DEV/Documents/DEV/My_project/telebot_helpman/help_work_bot/.venv/lib/python3.9/site-packages/requests/adapters.py", line 532, in send
    raise ReadTimeout(e, request=request)
requests.exceptions.ReadTimeout: HTTPSConnectionPool(host='api.telegram.org', port=443): Read timed out. (read timeout=25)

2024-03-12 04:45:09,508 [ERROR]: Infinity polling exception: HTTPSConnectionPool(host='api.telegram.org', port=443): Max retries exceeded with url: /bot6863293806:AAH3rusajaRMnCL82Og4HlCvPFDzOBh4dVw/getUpdates?offset=937875139&timeout=20 (Caused by NameResolutionError("<urllib3.connection.HTTPSConnection object at 0x10f37a550>: Failed to resolve 'api.telegram.org' ([Errno 8] nodename nor servname provided, or not known)"))
2024-03-12 04:45:09,542 [ERROR]: Exception traceback:
Traceback (most recent call last):
  File "/Users/Nick_DEV/Documents/DEV/My_project/telebot_helpman/help_work_bot/.venv/lib/python3.9/site-packages/urllib3/connection.py", line 200, in _new_conn
    sock = connection.create_connection(
  File "/Users/Nick_DEV/Documents/DEV/My_project/telebot_helpman/help_work_bot/.venv/lib/python3.9/site-packages/urllib3/util/connection.py", line 60, in create_connection
    for res in socket.getaddrinfo(host, port, family, socket.SOCK_STREAM):
  File "/usr/local/Cellar/python@3.9/3.9.18/Frameworks/Python.framework/Versions/3.9/lib/python3.9/socket.py", line 954, in getaddrinfo
    for res in _socket.getaddrinfo(host, port, family, type, proto, flags):
socket.gaierror: [Errno 8] nodename nor servname provided, or not known

The above exception was the direct cause of the following exception:

Traceback (most recent call last):
  File "/Users/Nick_DEV/Documents/DEV/My_project/telebot_helpman/help_work_bot/.venv/lib/python3.9/site-packages/urllib3/connectionpool.py", line 790, in urlopen
    response = self._make_request(
  File "/Users/Nick_DEV/Documents/DEV/My_project/telebot_helpman/help_work_bot/.venv/lib/python3.9/site-packages/urllib3/connectionpool.py", line 491, in _make_request
    raise new_e
  File "/Users/Nick_DEV/Documents/DEV/My_project/telebot_helpman/help_work_bot/.venv/lib/python3.9/site-packages/urllib3/connectionpool.py", line 467, in _make_request
    self._validate_conn(conn)
  File "/Users/Nick_DEV/Documents/DEV/My_project/telebot_helpman/help_work_bot/.venv/lib/python3.9/site-packages/urllib3/connectionpool.py", line 1092, in _validate_conn
    conn.connect()
  File "/Users/Nick_DEV/Documents/DEV/My_project/telebot_helpman/help_work_bot/.venv/lib/python3.9/site-packages/urllib3/connection.py", line 604, in connect
    self.sock = sock = self._new_conn()
  File "/Users/Nick_DEV/Documents/DEV/My_project/telebot_helpman/help_work_bot/.venv/lib/python3.9/site-packages/urllib3/connection.py", line 207, in _new_conn
    raise NameResolutionError(self.host, self, e) from e
urllib3.exceptions.NameResolutionError: <urllib3.connection.HTTPSConnection object at 0x10f37a550>: Failed to resolve 'api.telegram.org' ([Errno 8] nodename nor servname provided, or not known)

The above exception was the direct cause of the following exception:

Traceback (most recent call last):
  File "/Users/Nick_DEV/Documents/DEV/My_project/telebot_helpman/help_work_bot/.venv/lib/python3.9/site-packages/requests/adapters.py", line 486, in send
    resp = conn.urlopen(
  File "/Users/Nick_DEV/Documents/DEV/My_project/telebot_helpman/help_work_bot/.venv/lib/python3.9/site-packages/urllib3/connectionpool.py", line 844, in urlopen
    retries = retries.increment(
  File "/Users/Nick_DEV/Documents/DEV/My_project/telebot_helpman/help_work_bot/.venv/lib/python3.9/site-packages/urllib3/util/retry.py", line 515, in increment
    raise MaxRetryError(_pool, url, reason) from reason  # type: ignore[arg-type]
urllib3.exceptions.MaxRetryError: HTTPSConnectionPool(host='api.telegram.org', port=443): Max retries exceeded with url: /bot6863293806:AAH3rusajaRMnCL82Og4HlCvPFDzOBh4dVw/getUpdates?offset=937875139&timeout=20 (Caused by NameResolutionError("<urllib3.connection.HTTPSConnection object at 0x10f37a550>: Failed to resolve 'api.telegram.org' ([Errno 8] nodename nor servname provided, or not known)"))

During handling of the above exception, another exception occurred:

Traceback (most recent call last):
  File "/Users/Nick_DEV/Documents/DEV/My_project/telebot_helpman/help_work_bot/.venv/lib/python3.9/site-packages/telebot/__init__.py", line 955, in infinity_polling
    self.polling(non_stop=True, timeout=timeout, long_polling_timeout=long_polling_timeout,
  File "/Users/Nick_DEV/Documents/DEV/My_project/telebot_helpman/help_work_bot/.venv/lib/python3.9/site-packages/telebot/__init__.py", line 1043, in polling
    self.__threaded_polling(non_stop=non_stop, interval=interval, timeout=timeout, long_polling_timeout=long_polling_timeout,
  File "/Users/Nick_DEV/Documents/DEV/My_project/telebot_helpman/help_work_bot/.venv/lib/python3.9/site-packages/telebot/__init__.py", line 1118, in __threaded_polling
    raise e
  File "/Users/Nick_DEV/Documents/DEV/My_project/telebot_helpman/help_work_bot/.venv/lib/python3.9/site-packages/telebot/__init__.py", line 1073, in __threaded_polling
    polling_thread.raise_exceptions()
  File "/Users/Nick_DEV/Documents/DEV/My_project/telebot_helpman/help_work_bot/.venv/lib/python3.9/site-packages/telebot/util.py", line 108, in raise_exceptions
    raise self.exception_info
  File "/Users/Nick_DEV/Documents/DEV/My_project/telebot_helpman/help_work_bot/.venv/lib/python3.9/site-packages/telebot/util.py", line 90, in run
    task(*args, **kwargs)
  File "/Users/Nick_DEV/Documents/DEV/My_project/telebot_helpman/help_work_bot/.venv/lib/python3.9/site-packages/telebot/__init__.py", line 649, in __retrieve_updates
    updates = self.get_updates(offset=(self.last_update_id + 1),
  File "/Users/Nick_DEV/Documents/DEV/My_project/telebot_helpman/help_work_bot/.venv/lib/python3.9/site-packages/telebot/__init__.py", line 623, in get_updates
    json_updates = apihelper.get_updates(self.token, offset, limit, timeout, allowed_updates, long_polling_timeout)
  File "/Users/Nick_DEV/Documents/DEV/My_project/telebot_helpman/help_work_bot/.venv/lib/python3.9/site-packages/telebot/apihelper.py", line 321, in get_updates
    return _make_request(token, method_url, params=payload)
  File "/Users/Nick_DEV/Documents/DEV/My_project/telebot_helpman/help_work_bot/.venv/lib/python3.9/site-packages/telebot/apihelper.py", line 156, in _make_request
    result = _get_req_session().request(
  File "/Users/Nick_DEV/Documents/DEV/My_project/telebot_helpman/help_work_bot/.venv/lib/python3.9/site-packages/requests/sessions.py", line 589, in request
    resp = self.send(prep, **send_kwargs)
  File "/Users/Nick_DEV/Documents/DEV/My_project/telebot_helpman/help_work_bot/.venv/lib/python3.9/site-packages/requests/sessions.py", line 703, in send
    r = adapter.send(request, **kwargs)
  File "/Users/Nick_DEV/Documents/DEV/My_project/telebot_helpman/help_work_bot/.venv/lib/python3.9/site-packages/requests/adapters.py", line 519, in send
    raise ConnectionError(e, request=request)
requests.exceptions.ConnectionError: HTTPSConnectionPool(host='api.telegram.org', port=443): Max retries exceeded with url: /bot6863293806:AAH3rusajaRMnCL82Og4HlCvPFDzOBh4dVw/getUpdates?offset=937875139&timeout=20 (Caused by NameResolutionError("<urllib3.connection.HTTPSConnection object at 0x10f37a550>: Failed to resolve 'api.telegram.org' ([Errno 8] nodename nor servname provided, or not known)"))

2024-03-12 04:45:12,581 [ERROR]: Infinity polling exception: HTTPSConnectionPool(host='api.telegram.org', port=443): Max retries exceeded with url: /bot6863293806:AAH3rusajaRMnCL82Og4HlCvPFDzOBh4dVw/getUpdates?offset=937875139&timeout=20 (Caused by NameResolutionError("<urllib3.connection.HTTPSConnection object at 0x10f3827c0>: Failed to resolve 'api.telegram.org' ([Errno 8] nodename nor servname provided, or not known)"))
2024-03-12 04:45:12,583 [ERROR]: Exception traceback:
Traceback (most recent call last):
  File "/Users/Nick_DEV/Documents/DEV/My_project/telebot_helpman/help_work_bot/.venv/lib/python3.9/site-packages/urllib3/connection.py", line 200, in _new_conn
    sock = connection.create_connection(
  File "/Users/Nick_DEV/Documents/DEV/My_project/telebot_helpman/help_work_bot/.venv/lib/python3.9/site-packages/urllib3/util/connection.py", line 60, in create_connection
    for res in socket.getaddrinfo(host, port, family, socket.SOCK_STREAM):
  File "/usr/local/Cellar/python@3.9/3.9.18/Frameworks/Python.framework/Versions/3.9/lib/python3.9/socket.py", line 954, in getaddrinfo
    for res in _socket.getaddrinfo(host, port, family, type, proto, flags):
socket.gaierror: [Errno 8] nodename nor servname provided, or not known

The above exception was the direct cause of the following exception:

Traceback (most recent call last):
  File "/Users/Nick_DEV/Documents/DEV/My_project/telebot_helpman/help_work_bot/.venv/lib/python3.9/site-packages/urllib3/connectionpool.py", line 790, in urlopen
    response = self._make_request(
  File "/Users/Nick_DEV/Documents/DEV/My_project/telebot_helpman/help_work_bot/.venv/lib/python3.9/site-packages/urllib3/connectionpool.py", line 491, in _make_request
    raise new_e
  File "/Users/Nick_DEV/Documents/DEV/My_project/telebot_helpman/help_work_bot/.venv/lib/python3.9/site-packages/urllib3/connectionpool.py", line 467, in _make_request
    self._validate_conn(conn)
  File "/Users/Nick_DEV/Documents/DEV/My_project/telebot_helpman/help_work_bot/.venv/lib/python3.9/site-packages/urllib3/connectionpool.py", line 1092, in _validate_conn
    conn.connect()
  File "/Users/Nick_DEV/Documents/DEV/My_project/telebot_helpman/help_work_bot/.venv/lib/python3.9/site-packages/urllib3/connection.py", line 604, in connect
    self.sock = sock = self._new_conn()
  File "/Users/Nick_DEV/Documents/DEV/My_project/telebot_helpman/help_work_bot/.venv/lib/python3.9/site-packages/urllib3/connection.py", line 207, in _new_conn
    raise NameResolutionError(self.host, self, e) from e
urllib3.exceptions.NameResolutionError: <urllib3.connection.HTTPSConnection object at 0x10f3827c0>: Failed to resolve 'api.telegram.org' ([Errno 8] nodename nor servname provided, or not known)

The above exception was the direct cause of the following exception:

Traceback (most recent call last):
  File "/Users/Nick_DEV/Documents/DEV/My_project/telebot_helpman/help_work_bot/.venv/lib/python3.9/site-packages/requests/adapters.py", line 486, in send
    resp = conn.urlopen(
  File "/Users/Nick_DEV/Documents/DEV/My_project/telebot_helpman/help_work_bot/.venv/lib/python3.9/site-packages/urllib3/connectionpool.py", line 844, in urlopen
    retries = retries.increment(
  File "/Users/Nick_DEV/Documents/DEV/My_project/telebot_helpman/help_work_bot/.venv/lib/python3.9/site-packages/urllib3/util/retry.py", line 515, in increment
    raise MaxRetryError(_pool, url, reason) from reason  # type: ignore[arg-type]
urllib3.exceptions.MaxRetryError: HTTPSConnectionPool(host='api.telegram.org', port=443): Max retries exceeded with url: /bot6863293806:AAH3rusajaRMnCL82Og4HlCvPFDzOBh4dVw/getUpdates?offset=937875139&timeout=20 (Caused by NameResolutionError("<urllib3.connection.HTTPSConnection object at 0x10f3827c0>: Failed to resolve 'api.telegram.org' ([Errno 8] nodename nor servname provided, or not known)"))

During handling of the above exception, another exception occurred:

Traceback (most recent call last):
  File "/Users/Nick_DEV/Documents/DEV/My_project/telebot_helpman/help_work_bot/.venv/lib/python3.9/site-packages/telebot/__init__.py", line 955, in infinity_polling
    self.polling(non_stop=True, timeout=timeout, long_polling_timeout=long_polling_timeout,
  File "/Users/Nick_DEV/Documents/DEV/My_project/telebot_helpman/help_work_bot/.venv/lib/python3.9/site-packages/telebot/__init__.py", line 1043, in polling
    self.__threaded_polling(non_stop=non_stop, interval=interval, timeout=timeout, long_polling_timeout=long_polling_timeout,
  File "/Users/Nick_DEV/Documents/DEV/My_project/telebot_helpman/help_work_bot/.venv/lib/python3.9/site-packages/telebot/__init__.py", line 1118, in __threaded_polling
    raise e
  File "/Users/Nick_DEV/Documents/DEV/My_project/telebot_helpman/help_work_bot/.venv/lib/python3.9/site-packages/telebot/__init__.py", line 1073, in __threaded_polling
    polling_thread.raise_exceptions()
  File "/Users/Nick_DEV/Documents/DEV/My_project/telebot_helpman/help_work_bot/.venv/lib/python3.9/site-packages/telebot/util.py", line 108, in raise_exceptions
    raise self.exception_info
  File "/Users/Nick_DEV/Documents/DEV/My_project/telebot_helpman/help_work_bot/.venv/lib/python3.9/site-packages/telebot/util.py", line 90, in run
    task(*args, **kwargs)
  File "/Users/Nick_DEV/Documents/DEV/My_project/telebot_helpman/help_work_bot/.venv/lib/python3.9/site-packages/telebot/__init__.py", line 649, in __retrieve_updates
    updates = self.get_updates(offset=(self.last_update_id + 1),
  File "/Users/Nick_DEV/Documents/DEV/My_project/telebot_helpman/help_work_bot/.venv/lib/python3.9/site-packages/telebot/__init__.py", line 623, in get_updates
    json_updates = apihelper.get_updates(self.token, offset, limit, timeout, allowed_updates, long_polling_timeout)
  File "/Users/Nick_DEV/Documents/DEV/My_project/telebot_helpman/help_work_bot/.venv/lib/python3.9/site-packages/telebot/apihelper.py", line 321, in get_updates
    return _make_request(token, method_url, params=payload)
  File "/Users/Nick_DEV/Documents/DEV/My_project/telebot_helpman/help_work_bot/.venv/lib/python3.9/site-packages/telebot/apihelper.py", line 156, in _make_request
    result = _get_req_session().request(
  File "/Users/Nick_DEV/Documents/DEV/My_project/telebot_helpman/help_work_bot/.venv/lib/python3.9/site-packages/requests/sessions.py", line 589, in request
    resp = self.send(prep, **send_kwargs)
  File "/Users/Nick_DEV/Documents/DEV/My_project/telebot_helpman/help_work_bot/.venv/lib/python3.9/site-packages/requests/sessions.py", line 703, in send
    r = adapter.send(request, **kwargs)
  File "/Users/Nick_DEV/Documents/DEV/My_project/telebot_helpman/help_work_bot/.venv/lib/python3.9/site-packages/requests/adapters.py", line 519, in send
    raise ConnectionError(e, request=request)
requests.exceptions.ConnectionError: HTTPSConnectionPool(host='api.telegram.org', port=443): Max retries exceeded with url: /bot6863293806:AAH3rusajaRMnCL82Og4HlCvPFDzOBh4dVw/getUpdates?offset=937875139&timeout=20 (Caused by NameResolutionError("<urllib3.connection.HTTPSConnection object at 0x10f3827c0>: Failed to resolve 'api.telegram.org' ([Errno 8] nodename nor servname provided, or not known)"))

2024-03-12 05:58:13,857 [ERROR]: Infinity polling exception: HTTPSConnectionPool(host='api.telegram.org', port=443): Read timed out. (read timeout=25)
2024-03-12 05:58:13,890 [ERROR]: Exception traceback:
Traceback (most recent call last):
  File "/Users/Nick_DEV/Documents/DEV/My_project/telebot_helpman/help_work_bot/.venv/lib/python3.9/site-packages/urllib3/connectionpool.py", line 536, in _make_request
    response = conn.getresponse()
  File "/Users/Nick_DEV/Documents/DEV/My_project/telebot_helpman/help_work_bot/.venv/lib/python3.9/site-packages/urllib3/connection.py", line 454, in getresponse
    httplib_response = super().getresponse()
  File "/usr/local/Cellar/python@3.9/3.9.18/Frameworks/Python.framework/Versions/3.9/lib/python3.9/http/client.py", line 1377, in getresponse
    response.begin()
  File "/usr/local/Cellar/python@3.9/3.9.18/Frameworks/Python.framework/Versions/3.9/lib/python3.9/http/client.py", line 320, in begin
    version, status, reason = self._read_status()
  File "/usr/local/Cellar/python@3.9/3.9.18/Frameworks/Python.framework/Versions/3.9/lib/python3.9/http/client.py", line 281, in _read_status
    line = str(self.fp.readline(_MAXLINE + 1), "iso-8859-1")
  File "/usr/local/Cellar/python@3.9/3.9.18/Frameworks/Python.framework/Versions/3.9/lib/python3.9/socket.py", line 704, in readinto
    return self._sock.recv_into(b)
  File "/usr/local/Cellar/python@3.9/3.9.18/Frameworks/Python.framework/Versions/3.9/lib/python3.9/ssl.py", line 1275, in recv_into
    return self.read(nbytes, buffer)
  File "/usr/local/Cellar/python@3.9/3.9.18/Frameworks/Python.framework/Versions/3.9/lib/python3.9/ssl.py", line 1133, in read
    return self._sslobj.read(len, buffer)
socket.timeout: The read operation timed out

The above exception was the direct cause of the following exception:

Traceback (most recent call last):
  File "/Users/Nick_DEV/Documents/DEV/My_project/telebot_helpman/help_work_bot/.venv/lib/python3.9/site-packages/requests/adapters.py", line 486, in send
    resp = conn.urlopen(
  File "/Users/Nick_DEV/Documents/DEV/My_project/telebot_helpman/help_work_bot/.venv/lib/python3.9/site-packages/urllib3/connectionpool.py", line 844, in urlopen
    retries = retries.increment(
  File "/Users/Nick_DEV/Documents/DEV/My_project/telebot_helpman/help_work_bot/.venv/lib/python3.9/site-packages/urllib3/util/retry.py", line 470, in increment
    raise reraise(type(error), error, _stacktrace)
  File "/Users/Nick_DEV/Documents/DEV/My_project/telebot_helpman/help_work_bot/.venv/lib/python3.9/site-packages/urllib3/util/util.py", line 39, in reraise
    raise value
  File "/Users/Nick_DEV/Documents/DEV/My_project/telebot_helpman/help_work_bot/.venv/lib/python3.9/site-packages/urllib3/connectionpool.py", line 790, in urlopen
    response = self._make_request(
  File "/Users/Nick_DEV/Documents/DEV/My_project/telebot_helpman/help_work_bot/.venv/lib/python3.9/site-packages/urllib3/connectionpool.py", line 538, in _make_request
    self._raise_timeout(err=e, url=url, timeout_value=read_timeout)
  File "/Users/Nick_DEV/Documents/DEV/My_project/telebot_helpman/help_work_bot/.venv/lib/python3.9/site-packages/urllib3/connectionpool.py", line 370, in _raise_timeout
    raise ReadTimeoutError(
urllib3.exceptions.ReadTimeoutError: HTTPSConnectionPool(host='api.telegram.org', port=443): Read timed out. (read timeout=25)

During handling of the above exception, another exception occurred:

Traceback (most recent call last):
  File "/Users/Nick_DEV/Documents/DEV/My_project/telebot_helpman/help_work_bot/.venv/lib/python3.9/site-packages/telebot/__init__.py", line 955, in infinity_polling
    self.polling(non_stop=True, timeout=timeout, long_polling_timeout=long_polling_timeout,
  File "/Users/Nick_DEV/Documents/DEV/My_project/telebot_helpman/help_work_bot/.venv/lib/python3.9/site-packages/telebot/__init__.py", line 1043, in polling
    self.__threaded_polling(non_stop=non_stop, interval=interval, timeout=timeout, long_polling_timeout=long_polling_timeout,
  File "/Users/Nick_DEV/Documents/DEV/My_project/telebot_helpman/help_work_bot/.venv/lib/python3.9/site-packages/telebot/__init__.py", line 1118, in __threaded_polling
    raise e
  File "/Users/Nick_DEV/Documents/DEV/My_project/telebot_helpman/help_work_bot/.venv/lib/python3.9/site-packages/telebot/__init__.py", line 1073, in __threaded_polling
    polling_thread.raise_exceptions()
  File "/Users/Nick_DEV/Documents/DEV/My_project/telebot_helpman/help_work_bot/.venv/lib/python3.9/site-packages/telebot/util.py", line 108, in raise_exceptions
    raise self.exception_info
  File "/Users/Nick_DEV/Documents/DEV/My_project/telebot_helpman/help_work_bot/.venv/lib/python3.9/site-packages/telebot/util.py", line 90, in run
    task(*args, **kwargs)
  File "/Users/Nick_DEV/Documents/DEV/My_project/telebot_helpman/help_work_bot/.venv/lib/python3.9/site-packages/telebot/__init__.py", line 649, in __retrieve_updates
    updates = self.get_updates(offset=(self.last_update_id + 1),
  File "/Users/Nick_DEV/Documents/DEV/My_project/telebot_helpman/help_work_bot/.venv/lib/python3.9/site-packages/telebot/__init__.py", line 623, in get_updates
    json_updates = apihelper.get_updates(self.token, offset, limit, timeout, allowed_updates, long_polling_timeout)
  File "/Users/Nick_DEV/Documents/DEV/My_project/telebot_helpman/help_work_bot/.venv/lib/python3.9/site-packages/telebot/apihelper.py", line 321, in get_updates
    return _make_request(token, method_url, params=payload)
  File "/Users/Nick_DEV/Documents/DEV/My_project/telebot_helpman/help_work_bot/.venv/lib/python3.9/site-packages/telebot/apihelper.py", line 156, in _make_request
    result = _get_req_session().request(
  File "/Users/Nick_DEV/Documents/DEV/My_project/telebot_helpman/help_work_bot/.venv/lib/python3.9/site-packages/requests/sessions.py", line 589, in request
    resp = self.send(prep, **send_kwargs)
  File "/Users/Nick_DEV/Documents/DEV/My_project/telebot_helpman/help_work_bot/.venv/lib/python3.9/site-packages/requests/sessions.py", line 703, in send
    r = adapter.send(request, **kwargs)
  File "/Users/Nick_DEV/Documents/DEV/My_project/telebot_helpman/help_work_bot/.venv/lib/python3.9/site-packages/requests/adapters.py", line 532, in send
    raise ReadTimeout(e, request=request)
requests.exceptions.ReadTimeout: HTTPSConnectionPool(host='api.telegram.org', port=443): Read timed out. (read timeout=25)

2024-03-12 07:39:11,587 [ERROR]: Infinity polling exception: HTTPSConnectionPool(host='api.telegram.org', port=443): Max retries exceeded with url: /bot6863293806:AAH3rusajaRMnCL82Og4HlCvPFDzOBh4dVw/getUpdates?offset=937875139&timeout=20 (Caused by ConnectTimeoutError(<urllib3.connection.HTTPSConnection object at 0x10f37a880>, 'Connection to api.telegram.org timed out. (connect timeout=20)'))
2024-03-12 07:39:11,605 [ERROR]: Exception traceback:
Traceback (most recent call last):
  File "/Users/Nick_DEV/Documents/DEV/My_project/telebot_helpman/help_work_bot/.venv/lib/python3.9/site-packages/urllib3/connection.py", line 200, in _new_conn
    sock = connection.create_connection(
  File "/Users/Nick_DEV/Documents/DEV/My_project/telebot_helpman/help_work_bot/.venv/lib/python3.9/site-packages/urllib3/util/connection.py", line 85, in create_connection
    raise err
  File "/Users/Nick_DEV/Documents/DEV/My_project/telebot_helpman/help_work_bot/.venv/lib/python3.9/site-packages/urllib3/util/connection.py", line 73, in create_connection
    sock.connect(sa)
socket.timeout: timed out

The above exception was the direct cause of the following exception:

Traceback (most recent call last):
  File "/Users/Nick_DEV/Documents/DEV/My_project/telebot_helpman/help_work_bot/.venv/lib/python3.9/site-packages/urllib3/connectionpool.py", line 790, in urlopen
    response = self._make_request(
  File "/Users/Nick_DEV/Documents/DEV/My_project/telebot_helpman/help_work_bot/.venv/lib/python3.9/site-packages/urllib3/connectionpool.py", line 491, in _make_request
    raise new_e
  File "/Users/Nick_DEV/Documents/DEV/My_project/telebot_helpman/help_work_bot/.venv/lib/python3.9/site-packages/urllib3/connectionpool.py", line 467, in _make_request
    self._validate_conn(conn)
  File "/Users/Nick_DEV/Documents/DEV/My_project/telebot_helpman/help_work_bot/.venv/lib/python3.9/site-packages/urllib3/connectionpool.py", line 1092, in _validate_conn
    conn.connect()
  File "/Users/Nick_DEV/Documents/DEV/My_project/telebot_helpman/help_work_bot/.venv/lib/python3.9/site-packages/urllib3/connection.py", line 604, in connect
    self.sock = sock = self._new_conn()
  File "/Users/Nick_DEV/Documents/DEV/My_project/telebot_helpman/help_work_bot/.venv/lib/python3.9/site-packages/urllib3/connection.py", line 209, in _new_conn
    raise ConnectTimeoutError(
urllib3.exceptions.ConnectTimeoutError: (<urllib3.connection.HTTPSConnection object at 0x10f37a880>, 'Connection to api.telegram.org timed out. (connect timeout=20)')

The above exception was the direct cause of the following exception:

Traceback (most recent call last):
  File "/Users/Nick_DEV/Documents/DEV/My_project/telebot_helpman/help_work_bot/.venv/lib/python3.9/site-packages/requests/adapters.py", line 486, in send
    resp = conn.urlopen(
  File "/Users/Nick_DEV/Documents/DEV/My_project/telebot_helpman/help_work_bot/.venv/lib/python3.9/site-packages/urllib3/connectionpool.py", line 844, in urlopen
    retries = retries.increment(
  File "/Users/Nick_DEV/Documents/DEV/My_project/telebot_helpman/help_work_bot/.venv/lib/python3.9/site-packages/urllib3/util/retry.py", line 515, in increment
    raise MaxRetryError(_pool, url, reason) from reason  # type: ignore[arg-type]
urllib3.exceptions.MaxRetryError: HTTPSConnectionPool(host='api.telegram.org', port=443): Max retries exceeded with url: /bot6863293806:AAH3rusajaRMnCL82Og4HlCvPFDzOBh4dVw/getUpdates?offset=937875139&timeout=20 (Caused by ConnectTimeoutError(<urllib3.connection.HTTPSConnection object at 0x10f37a880>, 'Connection to api.telegram.org timed out. (connect timeout=20)'))

During handling of the above exception, another exception occurred:

Traceback (most recent call last):
  File "/Users/Nick_DEV/Documents/DEV/My_project/telebot_helpman/help_work_bot/.venv/lib/python3.9/site-packages/telebot/__init__.py", line 955, in infinity_polling
    self.polling(non_stop=True, timeout=timeout, long_polling_timeout=long_polling_timeout,
  File "/Users/Nick_DEV/Documents/DEV/My_project/telebot_helpman/help_work_bot/.venv/lib/python3.9/site-packages/telebot/__init__.py", line 1043, in polling
    self.__threaded_polling(non_stop=non_stop, interval=interval, timeout=timeout, long_polling_timeout=long_polling_timeout,
  File "/Users/Nick_DEV/Documents/DEV/My_project/telebot_helpman/help_work_bot/.venv/lib/python3.9/site-packages/telebot/__init__.py", line 1118, in __threaded_polling
    raise e
  File "/Users/Nick_DEV/Documents/DEV/My_project/telebot_helpman/help_work_bot/.venv/lib/python3.9/site-packages/telebot/__init__.py", line 1073, in __threaded_polling
    polling_thread.raise_exceptions()
  File "/Users/Nick_DEV/Documents/DEV/My_project/telebot_helpman/help_work_bot/.venv/lib/python3.9/site-packages/telebot/util.py", line 108, in raise_exceptions
    raise self.exception_info
  File "/Users/Nick_DEV/Documents/DEV/My_project/telebot_helpman/help_work_bot/.venv/lib/python3.9/site-packages/telebot/util.py", line 90, in run
    task(*args, **kwargs)
  File "/Users/Nick_DEV/Documents/DEV/My_project/telebot_helpman/help_work_bot/.venv/lib/python3.9/site-packages/telebot/__init__.py", line 649, in __retrieve_updates
    updates = self.get_updates(offset=(self.last_update_id + 1),
  File "/Users/Nick_DEV/Documents/DEV/My_project/telebot_helpman/help_work_bot/.venv/lib/python3.9/site-packages/telebot/__init__.py", line 623, in get_updates
    json_updates = apihelper.get_updates(self.token, offset, limit, timeout, allowed_updates, long_polling_timeout)
  File "/Users/Nick_DEV/Documents/DEV/My_project/telebot_helpman/help_work_bot/.venv/lib/python3.9/site-packages/telebot/apihelper.py", line 321, in get_updates
    return _make_request(token, method_url, params=payload)
  File "/Users/Nick_DEV/Documents/DEV/My_project/telebot_helpman/help_work_bot/.venv/lib/python3.9/site-packages/telebot/apihelper.py", line 156, in _make_request
    result = _get_req_session().request(
  File "/Users/Nick_DEV/Documents/DEV/My_project/telebot_helpman/help_work_bot/.venv/lib/python3.9/site-packages/requests/sessions.py", line 589, in request
    resp = self.send(prep, **send_kwargs)
  File "/Users/Nick_DEV/Documents/DEV/My_project/telebot_helpman/help_work_bot/.venv/lib/python3.9/site-packages/requests/sessions.py", line 703, in send
    r = adapter.send(request, **kwargs)
  File "/Users/Nick_DEV/Documents/DEV/My_project/telebot_helpman/help_work_bot/.venv/lib/python3.9/site-packages/requests/adapters.py", line 507, in send
    raise ConnectTimeout(e, request=request)
requests.exceptions.ConnectTimeout: HTTPSConnectionPool(host='api.telegram.org', port=443): Max retries exceeded with url: /bot6863293806:AAH3rusajaRMnCL82Og4HlCvPFDzOBh4dVw/getUpdates?offset=937875139&timeout=20 (Caused by ConnectTimeoutError(<urllib3.connection.HTTPSConnection object at 0x10f37a880>, 'Connection to api.telegram.org timed out. (connect timeout=20)'))

2024-03-12 11:50:20,618 [ERROR]: Infinity polling exception: HTTPSConnectionPool(host='api.telegram.org', port=443): Max retries exceeded with url: /bot6863293806:AAH3rusajaRMnCL82Og4HlCvPFDzOBh4dVw/getUpdates?offset=937875139&timeout=20 (Caused by NewConnectionError('<urllib3.connection.HTTPSConnection object at 0x10f39a1c0>: Failed to establish a new connection: [Errno 60] Operation timed out'))
2024-03-12 11:50:20,632 [ERROR]: Exception traceback:
Traceback (most recent call last):
  File "/Users/Nick_DEV/Documents/DEV/My_project/telebot_helpman/help_work_bot/.venv/lib/python3.9/site-packages/urllib3/connection.py", line 200, in _new_conn
    sock = connection.create_connection(
  File "/Users/Nick_DEV/Documents/DEV/My_project/telebot_helpman/help_work_bot/.venv/lib/python3.9/site-packages/urllib3/util/connection.py", line 85, in create_connection
    raise err
  File "/Users/Nick_DEV/Documents/DEV/My_project/telebot_helpman/help_work_bot/.venv/lib/python3.9/site-packages/urllib3/util/connection.py", line 73, in create_connection
    sock.connect(sa)
TimeoutError: [Errno 60] Operation timed out

The above exception was the direct cause of the following exception:

Traceback (most recent call last):
  File "/Users/Nick_DEV/Documents/DEV/My_project/telebot_helpman/help_work_bot/.venv/lib/python3.9/site-packages/urllib3/connectionpool.py", line 790, in urlopen
    response = self._make_request(
  File "/Users/Nick_DEV/Documents/DEV/My_project/telebot_helpman/help_work_bot/.venv/lib/python3.9/site-packages/urllib3/connectionpool.py", line 491, in _make_request
    raise new_e
  File "/Users/Nick_DEV/Documents/DEV/My_project/telebot_helpman/help_work_bot/.venv/lib/python3.9/site-packages/urllib3/connectionpool.py", line 467, in _make_request
    self._validate_conn(conn)
  File "/Users/Nick_DEV/Documents/DEV/My_project/telebot_helpman/help_work_bot/.venv/lib/python3.9/site-packages/urllib3/connectionpool.py", line 1092, in _validate_conn
    conn.connect()
  File "/Users/Nick_DEV/Documents/DEV/My_project/telebot_helpman/help_work_bot/.venv/lib/python3.9/site-packages/urllib3/connection.py", line 604, in connect
    self.sock = sock = self._new_conn()
  File "/Users/Nick_DEV/Documents/DEV/My_project/telebot_helpman/help_work_bot/.venv/lib/python3.9/site-packages/urllib3/connection.py", line 215, in _new_conn
    raise NewConnectionError(
urllib3.exceptions.NewConnectionError: <urllib3.connection.HTTPSConnection object at 0x10f39a1c0>: Failed to establish a new connection: [Errno 60] Operation timed out

The above exception was the direct cause of the following exception:

Traceback (most recent call last):
  File "/Users/Nick_DEV/Documents/DEV/My_project/telebot_helpman/help_work_bot/.venv/lib/python3.9/site-packages/requests/adapters.py", line 486, in send
    resp = conn.urlopen(
  File "/Users/Nick_DEV/Documents/DEV/My_project/telebot_helpman/help_work_bot/.venv/lib/python3.9/site-packages/urllib3/connectionpool.py", line 844, in urlopen
    retries = retries.increment(
  File "/Users/Nick_DEV/Documents/DEV/My_project/telebot_helpman/help_work_bot/.venv/lib/python3.9/site-packages/urllib3/util/retry.py", line 515, in increment
    raise MaxRetryError(_pool, url, reason) from reason  # type: ignore[arg-type]
urllib3.exceptions.MaxRetryError: HTTPSConnectionPool(host='api.telegram.org', port=443): Max retries exceeded with url: /bot6863293806:AAH3rusajaRMnCL82Og4HlCvPFDzOBh4dVw/getUpdates?offset=937875139&timeout=20 (Caused by NewConnectionError('<urllib3.connection.HTTPSConnection object at 0x10f39a1c0>: Failed to establish a new connection: [Errno 60] Operation timed out'))

During handling of the above exception, another exception occurred:

Traceback (most recent call last):
  File "/Users/Nick_DEV/Documents/DEV/My_project/telebot_helpman/help_work_bot/.venv/lib/python3.9/site-packages/telebot/__init__.py", line 955, in infinity_polling
    self.polling(non_stop=True, timeout=timeout, long_polling_timeout=long_polling_timeout,
  File "/Users/Nick_DEV/Documents/DEV/My_project/telebot_helpman/help_work_bot/.venv/lib/python3.9/site-packages/telebot/__init__.py", line 1043, in polling
    self.__threaded_polling(non_stop=non_stop, interval=interval, timeout=timeout, long_polling_timeout=long_polling_timeout,
  File "/Users/Nick_DEV/Documents/DEV/My_project/telebot_helpman/help_work_bot/.venv/lib/python3.9/site-packages/telebot/__init__.py", line 1118, in __threaded_polling
    raise e
  File "/Users/Nick_DEV/Documents/DEV/My_project/telebot_helpman/help_work_bot/.venv/lib/python3.9/site-packages/telebot/__init__.py", line 1073, in __threaded_polling
    polling_thread.raise_exceptions()
  File "/Users/Nick_DEV/Documents/DEV/My_project/telebot_helpman/help_work_bot/.venv/lib/python3.9/site-packages/telebot/util.py", line 108, in raise_exceptions
    raise self.exception_info
  File "/Users/Nick_DEV/Documents/DEV/My_project/telebot_helpman/help_work_bot/.venv/lib/python3.9/site-packages/telebot/util.py", line 90, in run
    task(*args, **kwargs)
  File "/Users/Nick_DEV/Documents/DEV/My_project/telebot_helpman/help_work_bot/.venv/lib/python3.9/site-packages/telebot/__init__.py", line 649, in __retrieve_updates
    updates = self.get_updates(offset=(self.last_update_id + 1),
  File "/Users/Nick_DEV/Documents/DEV/My_project/telebot_helpman/help_work_bot/.venv/lib/python3.9/site-packages/telebot/__init__.py", line 623, in get_updates
    json_updates = apihelper.get_updates(self.token, offset, limit, timeout, allowed_updates, long_polling_timeout)
  File "/Users/Nick_DEV/Documents/DEV/My_project/telebot_helpman/help_work_bot/.venv/lib/python3.9/site-packages/telebot/apihelper.py", line 321, in get_updates
    return _make_request(token, method_url, params=payload)
  File "/Users/Nick_DEV/Documents/DEV/My_project/telebot_helpman/help_work_bot/.venv/lib/python3.9/site-packages/telebot/apihelper.py", line 156, in _make_request
    result = _get_req_session().request(
  File "/Users/Nick_DEV/Documents/DEV/My_project/telebot_helpman/help_work_bot/.venv/lib/python3.9/site-packages/requests/sessions.py", line 589, in request
    resp = self.send(prep, **send_kwargs)
  File "/Users/Nick_DEV/Documents/DEV/My_project/telebot_helpman/help_work_bot/.venv/lib/python3.9/site-packages/requests/sessions.py", line 703, in send
    r = adapter.send(request, **kwargs)
  File "/Users/Nick_DEV/Documents/DEV/My_project/telebot_helpman/help_work_bot/.venv/lib/python3.9/site-packages/requests/adapters.py", line 519, in send
    raise ConnectionError(e, request=request)
requests.exceptions.ConnectionError: HTTPSConnectionPool(host='api.telegram.org', port=443): Max retries exceeded with url: /bot6863293806:AAH3rusajaRMnCL82Og4HlCvPFDzOBh4dVw/getUpdates?offset=937875139&timeout=20 (Caused by NewConnectionError('<urllib3.connection.HTTPSConnection object at 0x10f39a1c0>: Failed to establish a new connection: [Errno 60] Operation timed out'))

2024-03-12 11:51:50,963 [ERROR]: Infinity polling: polling exited
2024-03-12 11:51:50,964 [ERROR]: Break infinity polling
2024-03-12 11:52:22,544 [ERROR]: Произошла ошибка: CustomUser matching query does not exist.
2024-03-12 11:52:52,724 [ERROR]: Произошла ошибка: CustomUser matching query does not exist.
2024-03-12 11:52:57,453 [ERROR]: Произошла ошибка: CustomUser matching query does not exist.
2024-03-12 11:53:56,535 [ERROR]: Произошла ошибка: CustomUser matching query does not exist.
2024-03-12 11:53:57,779 [ERROR]: Произошла ошибка: CustomUser matching query does not exist.
2024-03-12 11:54:03,982 [ERROR]: Infinity polling: polling exited
2024-03-12 11:54:03,983 [ERROR]: Break infinity polling
2024-03-12 11:54:16,093 [ERROR]: Произошла ошибка: CustomUser matching query does not exist.
2024-03-12 11:54:50,471 [ERROR]: Infinity polling: polling exited
2024-03-12 11:54:50,479 [ERROR]: Break infinity polling
2024-03-12 12:02:49,080 [ERROR]: Произошла ошибка: 'CustomUser' object has no attribute 'blok'
2024-03-12 12:03:38,556 [ERROR]: Infinity polling: polling exited
2024-03-12 12:03:38,564 [ERROR]: Break infinity polling
2024-03-12 12:03:52,217 [ERROR]: Произошла ошибка: [Errno 2] No such file or directory: '/Users/Nick_DEV/Documents/DEV/My_project/telebot_helpman/help_work_bot/helpmanbot/Instructions/1/Назад'
2024-03-12 12:03:56,050 [ERROR]: Произошла ошибка: [Errno 2] No such file or directory: '/Users/Nick_DEV/Documents/DEV/My_project/telebot_helpman/help_work_bot/helpmanbot/Instructions/2/Назад'
2024-03-12 12:05:27,229 [ERROR]: Infinity polling: polling exited
2024-03-12 12:05:27,258 [ERROR]: Break infinity polling
2024-03-12 14:42:43,792 [ERROR]: Произошла ошибка: [Errno 2] No such file or directory: '/Users/Nick_DEV/Documents/DEV/My_project/telebot_helpman/help_work_bot/helpmanbot/Instructions/1/Назад'
2024-03-12 14:42:53,828 [ERROR]: Произошла ошибка: [Errno 2] No such file or directory: '/Users/Nick_DEV/Documents/DEV/My_project/telebot_helpman/help_work_bot/helpmanbot/Instructions/1/Назад'
2024-03-12 14:51:29,858 [ERROR]: Infinity polling: polling exited
2024-03-12 14:51:29,861 [ERROR]: Break infinity polling
2024-03-12 14:51:52,935 [ERROR]: Произошла ошибка: [Errno 2] No such file or directory: '/Users/Nick_DEV/Documents/DEV/My_project/telebot_helpman/help_work_bot/helpmanbot/Instructions/Инфо. Актуальные образы'
2024-03-12 14:52:45,098 [ERROR]: Произошла ошибка: [Errno 2] No such file or directory: '/Users/Nick_DEV/Documents/DEV/My_project/telebot_helpman/help_work_bot/helpmanbot/Instructions/29 сеть'
2024-03-12 14:57:36,347 [ERROR]: Infinity polling: polling exited
2024-03-12 14:57:36,348 [ERROR]: Break infinity polling
2024-03-12 14:59:56,410 [ERROR]: Infinity polling: polling exited
2024-03-12 14:59:56,412 [ERROR]: Break infinity polling
2024-03-12 15:00:46,352 [ERROR]: Infinity polling exception: HTTPSConnectionPool(host='api.telegram.org', port=443): Max retries exceeded with url: /bot6863293806:AAH3rusajaRMnCL82Og4HlCvPFDzOBh4dVw/getUpdates?offset=937875174&timeout=20 (Caused by ProxyError('Unable to connect to proxy', RemoteDisconnected('Remote end closed connection without response')))
2024-03-12 15:00:46,356 [ERROR]: Exception traceback:
Traceback (most recent call last):
  File "/Users/Nick_DEV/Documents/DEV/My_project/telebot_helpman/help_work_bot/.venv/lib/python3.9/site-packages/urllib3/connectionpool.py", line 790, in urlopen
    response = self._make_request(
  File "/Users/Nick_DEV/Documents/DEV/My_project/telebot_helpman/help_work_bot/.venv/lib/python3.9/site-packages/urllib3/connectionpool.py", line 536, in _make_request
    response = conn.getresponse()
  File "/Users/Nick_DEV/Documents/DEV/My_project/telebot_helpman/help_work_bot/.venv/lib/python3.9/site-packages/urllib3/connection.py", line 454, in getresponse
    httplib_response = super().getresponse()
  File "/usr/local/Cellar/python@3.9/3.9.18/Frameworks/Python.framework/Versions/3.9/lib/python3.9/http/client.py", line 1377, in getresponse
    response.begin()
  File "/usr/local/Cellar/python@3.9/3.9.18/Frameworks/Python.framework/Versions/3.9/lib/python3.9/http/client.py", line 320, in begin
    version, status, reason = self._read_status()
  File "/usr/local/Cellar/python@3.9/3.9.18/Frameworks/Python.framework/Versions/3.9/lib/python3.9/http/client.py", line 289, in _read_status
    raise RemoteDisconnected("Remote end closed connection without"
http.client.RemoteDisconnected: Remote end closed connection without response

The above exception was the direct cause of the following exception:

urllib3.exceptions.ProxyError: ('Unable to connect to proxy', RemoteDisconnected('Remote end closed connection without response'))

The above exception was the direct cause of the following exception:

Traceback (most recent call last):
  File "/Users/Nick_DEV/Documents/DEV/My_project/telebot_helpman/help_work_bot/.venv/lib/python3.9/site-packages/requests/adapters.py", line 486, in send
    resp = conn.urlopen(
  File "/Users/Nick_DEV/Documents/DEV/My_project/telebot_helpman/help_work_bot/.venv/lib/python3.9/site-packages/urllib3/connectionpool.py", line 844, in urlopen
    retries = retries.increment(
  File "/Users/Nick_DEV/Documents/DEV/My_project/telebot_helpman/help_work_bot/.venv/lib/python3.9/site-packages/urllib3/util/retry.py", line 515, in increment
    raise MaxRetryError(_pool, url, reason) from reason  # type: ignore[arg-type]
urllib3.exceptions.MaxRetryError: HTTPSConnectionPool(host='api.telegram.org', port=443): Max retries exceeded with url: /bot6863293806:AAH3rusajaRMnCL82Og4HlCvPFDzOBh4dVw/getUpdates?offset=937875174&timeout=20 (Caused by ProxyError('Unable to connect to proxy', RemoteDisconnected('Remote end closed connection without response')))

During handling of the above exception, another exception occurred:

Traceback (most recent call last):
  File "/Users/Nick_DEV/Documents/DEV/My_project/telebot_helpman/help_work_bot/.venv/lib/python3.9/site-packages/telebot/__init__.py", line 955, in infinity_polling
    self.polling(non_stop=True, timeout=timeout, long_polling_timeout=long_polling_timeout,
  File "/Users/Nick_DEV/Documents/DEV/My_project/telebot_helpman/help_work_bot/.venv/lib/python3.9/site-packages/telebot/__init__.py", line 1043, in polling
    self.__threaded_polling(non_stop=non_stop, interval=interval, timeout=timeout, long_polling_timeout=long_polling_timeout,
  File "/Users/Nick_DEV/Documents/DEV/My_project/telebot_helpman/help_work_bot/.venv/lib/python3.9/site-packages/telebot/__init__.py", line 1118, in __threaded_polling
    raise e
  File "/Users/Nick_DEV/Documents/DEV/My_project/telebot_helpman/help_work_bot/.venv/lib/python3.9/site-packages/telebot/__init__.py", line 1073, in __threaded_polling
    polling_thread.raise_exceptions()
  File "/Users/Nick_DEV/Documents/DEV/My_project/telebot_helpman/help_work_bot/.venv/lib/python3.9/site-packages/telebot/util.py", line 108, in raise_exceptions
    raise self.exception_info
  File "/Users/Nick_DEV/Documents/DEV/My_project/telebot_helpman/help_work_bot/.venv/lib/python3.9/site-packages/telebot/util.py", line 90, in run
    task(*args, **kwargs)
  File "/Users/Nick_DEV/Documents/DEV/My_project/telebot_helpman/help_work_bot/.venv/lib/python3.9/site-packages/telebot/__init__.py", line 649, in __retrieve_updates
    updates = self.get_updates(offset=(self.last_update_id + 1),
  File "/Users/Nick_DEV/Documents/DEV/My_project/telebot_helpman/help_work_bot/.venv/lib/python3.9/site-packages/telebot/__init__.py", line 623, in get_updates
    json_updates = apihelper.get_updates(self.token, offset, limit, timeout, allowed_updates, long_polling_timeout)
  File "/Users/Nick_DEV/Documents/DEV/My_project/telebot_helpman/help_work_bot/.venv/lib/python3.9/site-packages/telebot/apihelper.py", line 321, in get_updates
    return _make_request(token, method_url, params=payload)
  File "/Users/Nick_DEV/Documents/DEV/My_project/telebot_helpman/help_work_bot/.venv/lib/python3.9/site-packages/telebot/apihelper.py", line 156, in _make_request
    result = _get_req_session().request(
  File "/Users/Nick_DEV/Documents/DEV/My_project/telebot_helpman/help_work_bot/.venv/lib/python3.9/site-packages/requests/sessions.py", line 589, in request
    resp = self.send(prep, **send_kwargs)
  File "/Users/Nick_DEV/Documents/DEV/My_project/telebot_helpman/help_work_bot/.venv/lib/python3.9/site-packages/requests/sessions.py", line 703, in send
    r = adapter.send(request, **kwargs)
  File "/Users/Nick_DEV/Documents/DEV/My_project/telebot_helpman/help_work_bot/.venv/lib/python3.9/site-packages/requests/adapters.py", line 513, in send
    raise ProxyError(e, request=request)
requests.exceptions.ProxyError: HTTPSConnectionPool(host='api.telegram.org', port=443): Max retries exceeded with url: /bot6863293806:AAH3rusajaRMnCL82Og4HlCvPFDzOBh4dVw/getUpdates?offset=937875174&timeout=20 (Caused by ProxyError('Unable to connect to proxy', RemoteDisconnected('Remote end closed connection without response')))

2024-03-12 15:01:04,558 [ERROR]: Infinity polling: polling exited
2024-03-12 15:01:04,559 [ERROR]: Break infinity polling
2024-03-12 15:02:39,103 [ERROR]: Произошла ошибка: [Errno 2] No such file or directory: '/Users/Nick_DEV/Documents/DEV/My_project/telebot_helpman/help_work_bot/helpmanbot/Instructions/1/1'
2024-03-12 19:12:58,246 [ERROR]: Infinity polling exception: HTTPSConnectionPool(host='api.telegram.org', port=443): Max retries exceeded with url: /bot6863293806:AAH3rusajaRMnCL82Og4HlCvPFDzOBh4dVw/getMe (Caused by NameResolutionError("<urllib3.connection.HTTPSConnection object at 0x10ef77d30>: Failed to resolve 'api.telegram.org' ([Errno 8] nodename nor servname provided, or not known)"))
2024-03-12 19:12:58,352 [ERROR]: Exception traceback:
Traceback (most recent call last):
  File "/Users/Nick_DEV/Documents/DEV/My_project/telebot_helpman/help_work_bot/.venv/lib/python3.9/site-packages/urllib3/connection.py", line 200, in _new_conn
    sock = connection.create_connection(
  File "/Users/Nick_DEV/Documents/DEV/My_project/telebot_helpman/help_work_bot/.venv/lib/python3.9/site-packages/urllib3/util/connection.py", line 60, in create_connection
    for res in socket.getaddrinfo(host, port, family, socket.SOCK_STREAM):
  File "/usr/local/Cellar/python@3.9/3.9.18/Frameworks/Python.framework/Versions/3.9/lib/python3.9/socket.py", line 954, in getaddrinfo
    for res in _socket.getaddrinfo(host, port, family, type, proto, flags):
socket.gaierror: [Errno 8] nodename nor servname provided, or not known

The above exception was the direct cause of the following exception:

Traceback (most recent call last):
  File "/Users/Nick_DEV/Documents/DEV/My_project/telebot_helpman/help_work_bot/.venv/lib/python3.9/site-packages/urllib3/connectionpool.py", line 790, in urlopen
    response = self._make_request(
  File "/Users/Nick_DEV/Documents/DEV/My_project/telebot_helpman/help_work_bot/.venv/lib/python3.9/site-packages/urllib3/connectionpool.py", line 491, in _make_request
    raise new_e
  File "/Users/Nick_DEV/Documents/DEV/My_project/telebot_helpman/help_work_bot/.venv/lib/python3.9/site-packages/urllib3/connectionpool.py", line 467, in _make_request
    self._validate_conn(conn)
  File "/Users/Nick_DEV/Documents/DEV/My_project/telebot_helpman/help_work_bot/.venv/lib/python3.9/site-packages/urllib3/connectionpool.py", line 1092, in _validate_conn
    conn.connect()
  File "/Users/Nick_DEV/Documents/DEV/My_project/telebot_helpman/help_work_bot/.venv/lib/python3.9/site-packages/urllib3/connection.py", line 604, in connect
    self.sock = sock = self._new_conn()
  File "/Users/Nick_DEV/Documents/DEV/My_project/telebot_helpman/help_work_bot/.venv/lib/python3.9/site-packages/urllib3/connection.py", line 207, in _new_conn
    raise NameResolutionError(self.host, self, e) from e
urllib3.exceptions.NameResolutionError: <urllib3.connection.HTTPSConnection object at 0x10ef77d30>: Failed to resolve 'api.telegram.org' ([Errno 8] nodename nor servname provided, or not known)

The above exception was the direct cause of the following exception:

Traceback (most recent call last):
  File "/Users/Nick_DEV/Documents/DEV/My_project/telebot_helpman/help_work_bot/.venv/lib/python3.9/site-packages/requests/adapters.py", line 486, in send
    resp = conn.urlopen(
  File "/Users/Nick_DEV/Documents/DEV/My_project/telebot_helpman/help_work_bot/.venv/lib/python3.9/site-packages/urllib3/connectionpool.py", line 844, in urlopen
    retries = retries.increment(
  File "/Users/Nick_DEV/Documents/DEV/My_project/telebot_helpman/help_work_bot/.venv/lib/python3.9/site-packages/urllib3/util/retry.py", line 515, in increment
    raise MaxRetryError(_pool, url, reason) from reason  # type: ignore[arg-type]
urllib3.exceptions.MaxRetryError: HTTPSConnectionPool(host='api.telegram.org', port=443): Max retries exceeded with url: /bot6863293806:AAH3rusajaRMnCL82Og4HlCvPFDzOBh4dVw/getMe (Caused by NameResolutionError("<urllib3.connection.HTTPSConnection object at 0x10ef77d30>: Failed to resolve 'api.telegram.org' ([Errno 8] nodename nor servname provided, or not known)"))

During handling of the above exception, another exception occurred:

Traceback (most recent call last):
  File "/Users/Nick_DEV/Documents/DEV/My_project/telebot_helpman/help_work_bot/.venv/lib/python3.9/site-packages/telebot/__init__.py", line 955, in infinity_polling
    self.polling(non_stop=True, timeout=timeout, long_polling_timeout=long_polling_timeout,
  File "/Users/Nick_DEV/Documents/DEV/My_project/telebot_helpman/help_work_bot/.venv/lib/python3.9/site-packages/telebot/__init__.py", line 1040, in polling
    logger.info('Starting your bot with username: [@%s]', self.user.username)
  File "/Users/Nick_DEV/Documents/DEV/My_project/telebot_helpman/help_work_bot/.venv/lib/python3.9/site-packages/telebot/__init__.py", line 273, in user
    self._user = self.get_me()
  File "/Users/Nick_DEV/Documents/DEV/My_project/telebot_helpman/help_work_bot/.venv/lib/python3.9/site-packages/telebot/__init__.py", line 1236, in get_me
    result = apihelper.get_me(self.token)
  File "/Users/Nick_DEV/Documents/DEV/My_project/telebot_helpman/help_work_bot/.venv/lib/python3.9/site-packages/telebot/apihelper.py", line 196, in get_me
    return _make_request(token, method_url)
  File "/Users/Nick_DEV/Documents/DEV/My_project/telebot_helpman/help_work_bot/.venv/lib/python3.9/site-packages/telebot/apihelper.py", line 156, in _make_request
    result = _get_req_session().request(
  File "/Users/Nick_DEV/Documents/DEV/My_project/telebot_helpman/help_work_bot/.venv/lib/python3.9/site-packages/requests/sessions.py", line 589, in request
    resp = self.send(prep, **send_kwargs)
  File "/Users/Nick_DEV/Documents/DEV/My_project/telebot_helpman/help_work_bot/.venv/lib/python3.9/site-packages/requests/sessions.py", line 703, in send
    r = adapter.send(request, **kwargs)
  File "/Users/Nick_DEV/Documents/DEV/My_project/telebot_helpman/help_work_bot/.venv/lib/python3.9/site-packages/requests/adapters.py", line 519, in send
    raise ConnectionError(e, request=request)
requests.exceptions.ConnectionError: HTTPSConnectionPool(host='api.telegram.org', port=443): Max retries exceeded with url: /bot6863293806:AAH3rusajaRMnCL82Og4HlCvPFDzOBh4dVw/getMe (Caused by NameResolutionError("<urllib3.connection.HTTPSConnection object at 0x10ef77d30>: Failed to resolve 'api.telegram.org' ([Errno 8] nodename nor servname provided, or not known)"))

2024-03-12 19:13:01,791 [ERROR]: Infinity polling exception: HTTPSConnectionPool(host='api.telegram.org', port=443): Max retries exceeded with url: /bot6863293806:AAH3rusajaRMnCL82Og4HlCvPFDzOBh4dVw/getMe (Caused by NameResolutionError("<urllib3.connection.HTTPSConnection object at 0x10ef92520>: Failed to resolve 'api.telegram.org' ([Errno 8] nodename nor servname provided, or not known)"))
2024-03-12 19:13:01,794 [ERROR]: Exception traceback:
Traceback (most recent call last):
  File "/Users/Nick_DEV/Documents/DEV/My_project/telebot_helpman/help_work_bot/.venv/lib/python3.9/site-packages/urllib3/connection.py", line 200, in _new_conn
    sock = connection.create_connection(
  File "/Users/Nick_DEV/Documents/DEV/My_project/telebot_helpman/help_work_bot/.venv/lib/python3.9/site-packages/urllib3/util/connection.py", line 60, in create_connection
    for res in socket.getaddrinfo(host, port, family, socket.SOCK_STREAM):
  File "/usr/local/Cellar/python@3.9/3.9.18/Frameworks/Python.framework/Versions/3.9/lib/python3.9/socket.py", line 954, in getaddrinfo
    for res in _socket.getaddrinfo(host, port, family, type, proto, flags):
socket.gaierror: [Errno 8] nodename nor servname provided, or not known

The above exception was the direct cause of the following exception:

Traceback (most recent call last):
  File "/Users/Nick_DEV/Documents/DEV/My_project/telebot_helpman/help_work_bot/.venv/lib/python3.9/site-packages/urllib3/connectionpool.py", line 790, in urlopen
    response = self._make_request(
  File "/Users/Nick_DEV/Documents/DEV/My_project/telebot_helpman/help_work_bot/.venv/lib/python3.9/site-packages/urllib3/connectionpool.py", line 491, in _make_request
    raise new_e
  File "/Users/Nick_DEV/Documents/DEV/My_project/telebot_helpman/help_work_bot/.venv/lib/python3.9/site-packages/urllib3/connectionpool.py", line 467, in _make_request
    self._validate_conn(conn)
  File "/Users/Nick_DEV/Documents/DEV/My_project/telebot_helpman/help_work_bot/.venv/lib/python3.9/site-packages/urllib3/connectionpool.py", line 1092, in _validate_conn
    conn.connect()
  File "/Users/Nick_DEV/Documents/DEV/My_project/telebot_helpman/help_work_bot/.venv/lib/python3.9/site-packages/urllib3/connection.py", line 604, in connect
    self.sock = sock = self._new_conn()
  File "/Users/Nick_DEV/Documents/DEV/My_project/telebot_helpman/help_work_bot/.venv/lib/python3.9/site-packages/urllib3/connection.py", line 207, in _new_conn
    raise NameResolutionError(self.host, self, e) from e
urllib3.exceptions.NameResolutionError: <urllib3.connection.HTTPSConnection object at 0x10ef92520>: Failed to resolve 'api.telegram.org' ([Errno 8] nodename nor servname provided, or not known)

The above exception was the direct cause of the following exception:

Traceback (most recent call last):
  File "/Users/Nick_DEV/Documents/DEV/My_project/telebot_helpman/help_work_bot/.venv/lib/python3.9/site-packages/requests/adapters.py", line 486, in send
    resp = conn.urlopen(
  File "/Users/Nick_DEV/Documents/DEV/My_project/telebot_helpman/help_work_bot/.venv/lib/python3.9/site-packages/urllib3/connectionpool.py", line 844, in urlopen
    retries = retries.increment(
  File "/Users/Nick_DEV/Documents/DEV/My_project/telebot_helpman/help_work_bot/.venv/lib/python3.9/site-packages/urllib3/util/retry.py", line 515, in increment
    raise MaxRetryError(_pool, url, reason) from reason  # type: ignore[arg-type]
urllib3.exceptions.MaxRetryError: HTTPSConnectionPool(host='api.telegram.org', port=443): Max retries exceeded with url: /bot6863293806:AAH3rusajaRMnCL82Og4HlCvPFDzOBh4dVw/getMe (Caused by NameResolutionError("<urllib3.connection.HTTPSConnection object at 0x10ef92520>: Failed to resolve 'api.telegram.org' ([Errno 8] nodename nor servname provided, or not known)"))

During handling of the above exception, another exception occurred:

Traceback (most recent call last):
  File "/Users/Nick_DEV/Documents/DEV/My_project/telebot_helpman/help_work_bot/.venv/lib/python3.9/site-packages/telebot/__init__.py", line 955, in infinity_polling
    self.polling(non_stop=True, timeout=timeout, long_polling_timeout=long_polling_timeout,
  File "/Users/Nick_DEV/Documents/DEV/My_project/telebot_helpman/help_work_bot/.venv/lib/python3.9/site-packages/telebot/__init__.py", line 1040, in polling
    logger.info('Starting your bot with username: [@%s]', self.user.username)
  File "/Users/Nick_DEV/Documents/DEV/My_project/telebot_helpman/help_work_bot/.venv/lib/python3.9/site-packages/telebot/__init__.py", line 273, in user
    self._user = self.get_me()
  File "/Users/Nick_DEV/Documents/DEV/My_project/telebot_helpman/help_work_bot/.venv/lib/python3.9/site-packages/telebot/__init__.py", line 1236, in get_me
    result = apihelper.get_me(self.token)
  File "/Users/Nick_DEV/Documents/DEV/My_project/telebot_helpman/help_work_bot/.venv/lib/python3.9/site-packages/telebot/apihelper.py", line 196, in get_me
    return _make_request(token, method_url)
  File "/Users/Nick_DEV/Documents/DEV/My_project/telebot_helpman/help_work_bot/.venv/lib/python3.9/site-packages/telebot/apihelper.py", line 156, in _make_request
    result = _get_req_session().request(
  File "/Users/Nick_DEV/Documents/DEV/My_project/telebot_helpman/help_work_bot/.venv/lib/python3.9/site-packages/requests/sessions.py", line 589, in request
    resp = self.send(prep, **send_kwargs)
  File "/Users/Nick_DEV/Documents/DEV/My_project/telebot_helpman/help_work_bot/.venv/lib/python3.9/site-packages/requests/sessions.py", line 703, in send
    r = adapter.send(request, **kwargs)
  File "/Users/Nick_DEV/Documents/DEV/My_project/telebot_helpman/help_work_bot/.venv/lib/python3.9/site-packages/requests/adapters.py", line 519, in send
    raise ConnectionError(e, request=request)
requests.exceptions.ConnectionError: HTTPSConnectionPool(host='api.telegram.org', port=443): Max retries exceeded with url: /bot6863293806:AAH3rusajaRMnCL82Og4HlCvPFDzOBh4dVw/getMe (Caused by NameResolutionError("<urllib3.connection.HTTPSConnection object at 0x10ef92520>: Failed to resolve 'api.telegram.org' ([Errno 8] nodename nor servname provided, or not known)"))

2024-03-12 19:40:26,790 [ERROR]: Infinity polling: polling exited
2024-03-12 19:40:26,792 [ERROR]: Break infinity polling
2024-03-12 19:41:55,322 [ERROR]: Infinity polling: polling exited
2024-03-12 19:41:55,322 [ERROR]: Break infinity polling
2024-03-12 19:42:42,056 [ERROR]: Infinity polling: polling exited
2024-03-12 19:42:42,057 [ERROR]: Break infinity polling
2024-03-12 19:43:01,258 [ERROR]: Произошла ошибка: [Errno 2] No such file or directory: '/Users/Nick_DEV/Documents/DEV/My_project/telebot_helpman/help_work_bot/helpmanbot/Instructions/1/2'
2024-03-12 19:50:22,714 [ERROR]: Infinity polling: polling exited
2024-03-12 19:50:22,715 [ERROR]: Break infinity polling
2024-03-12 19:50:45,796 [ERROR]: Произошла ошибка: [Errno 2] No such file or directory: '/Users/Nick_DEV/Documents/DEV/My_project/telebot_helpman/help_work_bot/helpmanbot/Instructions/1/1'
2024-03-12 19:50:55,353 [ERROR]: Произошла ошибка: [Errno 2] No such file or directory: '/Users/Nick_DEV/Documents/DEV/My_project/telebot_helpman/help_work_bot/helpmanbot/Instructions/1/1'
2024-03-12 19:51:30,740 [ERROR]: Произошла ошибка: CustomUser matching query does not exist.
2024-03-12 19:54:35,397 [ERROR]: Infinity polling: polling exited
2024-03-12 19:54:35,398 [ERROR]: Break infinity polling
2024-03-12 19:55:00,979 [ERROR]: Произошла ошибка: [Errno 2] No such file or directory: '/start'
2024-03-12 19:55:18,518 [ERROR]: Произошла ошибка: [Errno 2] No such file or directory: '/Users/Nick_DEV/Documents/DEV/My_project/telebot_helpman/help_work_bot/helpmanbot/Instructions/1/1'
2024-03-12 19:55:33,518 [ERROR]: Произошла ошибка: [Errno 2] No such file or directory: '/Users/Nick_DEV/Documents/DEV/My_project/telebot_helpman/help_work_bot/helpmanbot/Instructions/2/2'
2024-03-12 19:59:38,321 [ERROR]: Infinity polling: polling exited
2024-03-12 19:59:38,321 [ERROR]: Break infinity polling
2024-03-12 20:00:00,003 [ERROR]: Произошла ошибка: [Errno 2] No such file or directory: '/Users/Nick_DEV/Documents/DEV/My_project/telebot_helpman/help_work_bot/helpmanbot/Instructions/1/1'
2024-03-12 20:02:12,829 [ERROR]: Infinity polling: polling exited
2024-03-12 20:02:12,834 [ERROR]: Break infinity polling
2024-03-12 20:02:31,616 [ERROR]: Произошла ошибка: [Errno 2] No such file or directory: '/Users/Nick_DEV/Documents/DEV/My_project/telebot_helpman/help_work_bot/helpmanbot/Instructions/1/1'
2024-03-12 20:06:01,523 [ERROR]: Infinity polling: polling exited
2024-03-12 20:06:01,525 [ERROR]: Break infinity polling
2024-03-12 20:07:54,936 [ERROR]: Infinity polling: polling exited
2024-03-12 20:07:54,938 [ERROR]: Break infinity polling
2024-03-12 20:09:08,973 [ERROR]: Произошла ошибка: [Errno 2] No such file or directory: '/Users/Nick_DEV/Documents/DEV/My_project/telebot_helpman/help_work_bot/helpmanbot/Instructions/Инфо. Актуальные образы'
2024-03-12 20:12:12,771 [ERROR]: Произошла ошибка: A request to the Telegram API was unsuccessful. Error code: 400. Description: Bad Request: file must be non-empty
2024-03-12 20:16:13,429 [ERROR]: Infinity polling: polling exited
2024-03-12 20:16:13,432 [ERROR]: Break infinity polling
2024-03-12 20:18:09,109 [ERROR]: Произошла ошибка: [Errno 2] No such file or directory: '/Users/Nick_DEV/Documents/DEV/My_project/telebot_helpman/help_work_bot/helpmanbot/Instructions/1/1'
